Workbook

Sheet Info Desa
A1: Profil Desa Sukamaju (Simulasi)
A2: DATA SIMULASI UNTUK PROTOTIPE — desa, wilayah, dan angka ini FIKTIF, bukan data desa nyata.
A4: Nama desa | B4: Desa Sukamaju (Simulasi)
A5: Kecamatan | B5: Kecamatan Contoh (fiktif)
A6: Kabupaten | B6: Kabupaten Simulasi (fiktif)
A7: Tahun anggaran | B7: 2026
A8: Posisi realisasi | B8: s.d. 30 September 2026
A9: Jumlah penduduk | B9: 4180
A10: Jumlah kepala keluarga | B10: 1265
A11: Jumlah dusun | B11: 4
A12: Jumlah RT | B12: 12
A14: Pembagian wilayah
A15: Dusun | B15: RT | C15: Keterangan
A16: Krajan | B16: RT 01 – RT 03 | C16: Pusat desa, kantor desa, pasar desa
A17: Karangrejo | B17: RT 04 – RT 06 | C17: Permukiman padat, rawan longsor di tebing sungai
A18: Ngemplak | B18: RT 07 – RT 09 | C18: Sebagian warga belum terlayani air bersih
A19: Tegalsari | B19: RT 10 – RT 12 | C19: Wilayah persawahan, jalan usaha tani gelap malam hari
A21: Cara memakai file ini
A22: 1. Sheet 'APBDes 2026' adalah dokumen yang diunggah ke sistem saat demo (fitur Unggah).
A23: 2. Teks biru = angka/isian yang boleh diubah. Teks hitam = rumus, jangan ditimpa.
A24: 3. Sheet 'Ringkasan' dihitung otomatis dari APBDes, dipakai untuk mengecek jawaban AI.
A25: 4. Sheet 'Pertanyaan Uji' berisi pertanyaan + kunci jawaban (rumus) untuk mengukur ketepatan AI.
A26: 5. Sheet 'Aspirasi Contoh' berisi masukan warga fiktif untuk demo fitur pengelompokan aspirasi.
A27: 6. Struktur kode rekening dan bidang mengikuti pola APBDes pada umumnya; cocokkan dengan APBDes asli atau regulasi terbaru sebelum dipakai di proposal.
A28: 7. Semua nominal bersifat ilustratif (skala dibuat masuk akal), bukan pagu resmi.

Sheet APBDes 2026
A1: APBDes Desa Sukamaju (Simulasi) — Tahun Anggaran 2026
A2: DATA SIMULASI UNTUK PROTOTIPE — desa, wilayah, dan angka ini FIKTIF, bukan data desa nyata.
A4: No | B4: Kode Rekening | C4: Jenis | D4: Bidang | E4: Uraian | F4: Dusun | G4: RT | H4: Sumber Dana | I4: Anggaran (Rp) | J4: Realisasi s.d. 30 Sep 2026 (Rp) | K4: % Realisasi | L4: Status | M4: Keterangan
A5: PENDAPATAN
A6: 1 | B6: 4.1.1 | C6: Pendapatan | D6: - | E6: Hasil usaha desa (bagi hasil BUMDes) | F6: Seluruh desa | G6: - | H6: PADes | I6: 30000000 | J6: 18000000 | K6: =IF(I6=0,0,J6/I6) -> 0.6 | L6: Diterima sebagian
A7: 2 | B7: 4.1.2 | C7: Pendapatan | D7: - | E7: Hasil aset desa (sewa tanah kas desa) | F7: Seluruh desa | G7: - | H7: PADes | I7: 25000000 | J7: 25000000 | K7: =IF(I7=0,0,J7/I7) -> 1 | L7: Diterima
A8: 3 | B8: 4.1.3 | C8: Pendapatan | D8: - | E8: Swadaya, partisipasi, dan gotong royong | F8: Seluruh desa | G8: - | H8: PADes | I8: 10000000 | J8: 6000000 | K8: =IF(I8=0,0,J8/I8) -> 0.6 | L8: Diterima sebagian
A9: 4 | B9: 4.2.1 | C9: Pendapatan | D9: - | E9: Dana Desa | F9: Seluruh desa | G9: - | H9: Dana Desa | I9: 939000000 | J9: 657300000 | K9: =IF(I9=0,0,J9/I9) -> 0.7 | L9: Diterima sebagian | M9: Tahap 1 dan 2 sudah cair (70%)
A10: 5 | B10: 4.2.2 | C10: Pendapatan | D10: - | E10: Bagian dari hasil pajak dan retribusi daerah | F10: Seluruh desa | G10: - | H10: Bagi Hasil Pajak | I10: 30000000 | J10: 20000000 | K10: =IF(I10=0,0,J10/I10) -> 0.66666667 | L10: Diterima sebagian
A11: 6 | B11: 4.2.3 | C11: Pendapatan | D11: - | E11: Alokasi Dana Desa (ADD) | F11: Seluruh desa | G11: - | H11: ADD | I11: 422000000 | J11: 316500000 | K11: =IF(I11=0,0,J11/I11) -> 0.75 | L11: Diterima sebagian | M11: Cair per triwulan
A12: 7 | B12: 4.2.5 | C12: Pendapatan | D12: - | E12: Bantuan keuangan dari APBD kabupaten | F12: Seluruh desa | G12: - | H12: Bantuan Keuangan Kabupaten | I12: 50000000 | J12: 35000000 | K12: =IF(I12=0,0,J12/I12) -> 0.7 | L12: Diterima sebagian | M12: Untuk sarana air bersih Ngemplak
A13: BELANJA
A14: 8 | B14: 1.1.01 | C14: Belanja | D14: 1. Penyelenggaraan Pemerintahan Desa | E14: Penghasilan tetap kepala desa dan perangkat desa | F14: Seluruh desa | G14: - | H14: ADD | I14: 252000000 | J14: 189000000 | K14: =IF(I14=0,0,J14/I14) -> 0.75 | L14: Berjalan | M14: Dibayar bulanan, 9 dari 12 bulan
A15: 9 | B15: 1.1.02 | C15: Belanja | D15: 1. Penyelenggaraan Pemerintahan Desa | E15: Tunjangan kepala desa dan perangkat desa | F15: Seluruh desa | G15: - | H15: ADD | I15: 48000000 | J15: 36000000 | K15: =IF(I15=0,0,J15/I15) -> 0.75 | L15: Berjalan | M15: Dibayar bulanan
A16: 10 | B16: 1.1.03 | C16: Belanja | D16: 1. Penyelenggaraan Pemerintahan Desa | E16: Tunjangan dan operasional BPD | F16: Seluruh desa | G16: - | H16: ADD | I16: 36000000 | J16: 27000000 | K16: =IF(I16=0,0,J16/I16) -> 0.75 | L16: Berjalan | M16: 7 anggota BPD
A17: 11 | B17: 1.1.04 | C17: Belanja | D17: 1. Penyelenggaraan Pemerintahan Desa | E17: Operasional pemerintah desa (ATK, listrik, internet) | F17: Seluruh desa | G17: - | H17: ADD | I17: 42000000 | J17: 30500000 | K17: =IF(I17=0,0,J17/I17) -> 0.72619048 | L17: Berjalan
A18: 12 | B18: 1.2.01 | C18: Belanja | D18: 1. Penyelenggaraan Pemerintahan Desa | E18: Pemeliharaan gedung kantor desa | F18: Krajan | G18: 01 | H18: PADes | I18: 25000000 | J18: 25000000 | K18: =IF(I18=0,0,J18/I18) -> 1 | L18: Selesai | M18: Pengecatan dan perbaikan atap
A19: 13 | B19: 1.3.01 | C19: Belanja | D19: 1. Penyelenggaraan Pemerintahan Desa | E19: Penyusunan dokumen perencanaan (RKPDes dan APBDes) | F19: Seluruh desa | G19: - | H19: ADD | I19: 12000000 | J19: 6000000 | K19: =IF(I19=0,0,J19/I19) -> 0.5 | L19: Berjalan | M19: RKPDes 2027 sedang disusun
A20: 14 | B20: 1.4.01 | C20: Belanja | D20: 1. Penyelenggaraan Pemerintahan Desa | E20: Pemutakhiran data penduduk dan data sosial ekonomi desa | F20: Seluruh desa | G20: - | H20: ADD | I20: 8000000 | J20: 8000000 | K20: =IF(I20=0,0,J20/I20) -> 1 | L20: Selesai
A21: 15 | B21: 2.1.01 | C21: Belanja | D21: 2. Pelaksanaan Pembangunan Desa | E21: Pengaspalan jalan lingkungan Dusun Krajan RT 03 (panjang 250 m) | F21: Krajan | G21: 03 | H21: Dana Desa | I21: 185000000 | J21: 185000000 | K21: =IF(I21=0,0,J21/I21) -> 1 | L21: Selesai | M21: Selesai Juli 2026
A22: 16 | B22: 2.1.02 | C22: Belanja | D22: 2. Pelaksanaan Pembangunan Desa | E22: Rabat beton gang Dusun Karangrejo RT 05 (panjang 180 m) | F22: Karangrejo | G22: 05 | H22: Dana Desa | I22: 96000000 | J22: 48000000 | K22: =IF(I22=0,0,J22/I22) -> 0.5 | L22: Berjalan | M22: Progres fisik sekitar 50%
A23: 17 | B23: 2.1.03 | C23: Belanja | D23: 2. Pelaksanaan Pembangunan Desa | E23: Pembangunan talud penahan tebing sungai Dusun Karangrejo RT 06 | F23: Karangrejo | G23: 06 | H23: Dana Desa | I23: 70000000 | J23: 0 | K23: =IF(I23=0,0,J23/I23) -> 0 | L23: Belum dimulai | M23: Dijadwalkan November 2026
A24: 18 | B24: 2.1.04 | C24: Belanja | D24: 2. Pelaksanaan Pembangunan Desa | E24: Pembangunan saluran drainase Dusun Ngemplak RT 08 | F24: Ngemplak | G24: 08 | H24: Dana Desa | I24: 74000000 | J24: 51800000 | K24: =IF(I24=0,0,J24/I24) -> 0.7 | L24: Berjalan | M24: Progres fisik sekitar 70%
A25: 19 | B25: 2.1.05 | C25: Belanja | D25: 2. Pelaksanaan Pembangunan Desa | E25: Rehabilitasi saluran irigasi tersier Dusun Tegalsari RT 11 | F25: Tegalsari | G25: 11 | H25: Dana Desa | I25: 112000000 | J25: 112000000 | K25: =IF(I25=0,0,J25/I25) -> 1 | L25: Selesai | M25: Selesai sebelum musim tanam
A26: 20 | B26: 2.1.06 | C26: Belanja | D26: 2. Pelaksanaan Pembangunan Desa | E26: Penerangan jalan umum tenaga surya 10 titik Dusun Tegalsari | F26: Tegalsari | G26: 10-12 | H26: Dana Desa | I26: 65000000 | J26: 0 | K26: =IF(I26=0,0,J26/I26) -> 0 | L26: Belum dimulai | M26: Menunggu pencairan Dana Desa tahap akhir
A27: 21 | B27: 2.1.07 | C27: Belanja | D27: 2. Pelaksanaan Pembangunan Desa | E27: Pembangunan sarana air bersih Dusun Ngemplak RT 07 | F27: Ngemplak | G27: 07 | H27: Bantuan Keuangan Kabupaten | I27: 50000000 | J27: 35000000 | K27: =IF(I27=0,0,J27/I27) -> 0.7 | L27: Berjalan | M27: Sumur bor dan tandon
A28: 22 | B28: 2.2.01 | C28: Belanja | D28: 2. Pelaksanaan Pembangunan Desa | E28: Operasional posyandu (5 posyandu) | F28: Seluruh desa | G28: - | H28: Dana Desa | I28: 30000000 | J28: 22500000 | K28: =IF(I28=0,0,J28/I28) -> 0.75 | L28: Berjalan
A29: 23 | B29: 2.2.02 | C29: Belanja | D29: 2. Pelaksanaan Pembangunan Desa | E29: Pemberian makanan tambahan (PMT) balita dan ibu hamil untuk pencegahan stunting | F29: Seluruh desa | G29: - | H29: Dana Desa | I29: 48000000 | J29: 32000000 | K29: =IF(I29=0,0,J29/I29) -> 0.66666667 | L29: Berjalan | M29: Sasaran 64 balita dan 18 ibu hamil
A30: 24 | B30: 2.2.03 | C30: Belanja | D30: 2. Pelaksanaan Pembangunan Desa | E30: Insentif kader posyandu | F30: Seluruh desa | G30: - | H30: Dana Desa | I30: 36000000 | J30: 27000000 | K30: =IF(I30=0,0,J30/I30) -> 0.75 | L30: Berjalan | M30: 25 kader
A31: 25 | B31: 2.3.01 | C31: Belanja | D31: 2. Pelaksanaan Pembangunan Desa | E31: Insentif guru PAUD desa | F31: Seluruh desa | G31: - | H31: ADD | I31: 24000000 | J31: 18000000 | K31: =IF(I31=0,0,J31/I31) -> 0.75 | L31: Berjalan | M31: 4 guru PAUD
A32: 26 | B32: 3.1.01 | C32: Belanja | D32: 3. Pembinaan Kemasyarakatan Desa | E32: Pembinaan linmas dan keamanan lingkungan | F32: Seluruh desa | G32: - | H32: Bagi Hasil Pajak | I32: 12000000 | J32: 9000000 | K32: =IF(I32=0,0,J32/I32) -> 0.75 | L32: Berjalan
A33: 27 | B33: 3.2.01 | C33: Belanja | D33: 3. Pembinaan Kemasyarakatan Desa | E33: Kegiatan keagamaan dan pembinaan PKK | F33: Seluruh desa | G33: - | H33: Bagi Hasil Pajak | I33: 18000000 | J33: 11000000 | K33: =IF(I33=0,0,J33/I33) -> 0.61111111 | L33: Berjalan
A34: 28 | B34: 3.3.01 | C34: Belanja | D34: 3. Pembinaan Kemasyarakatan Desa | E34: Pembinaan karang taruna dan kegiatan olahraga pemuda | F34: Seluruh desa | G34: - | H34: PADes | I34: 15000000 | J34: 15000000 | K34: =IF(I34=0,0,J34/I34) -> 1 | L34: Selesai | M34: Turnamen voli antar-dusun Agustus 2026
A35: 29 | B35: 3.4.01 | C35: Belanja | D35: 3. Pembinaan Kemasyarakatan Desa | E35: Pelestarian budaya (merti desa) | F35: Seluruh desa | G35: - | H35: PADes | I35: 10000000 | J35: 10000000 | K35: =IF(I35=0,0,J35/I35) -> 1 | L35: Selesai
A36: 30 | B36: 4.1.01 | C36: Belanja | D36: 4. Pemberdayaan Masyarakat Desa | E36: Pelatihan pengolahan hasil pertanian untuk kelompok wanita tani | F36: Tegalsari | G36: - | H36: Dana Desa | I36: 20000000 | J36: 0 | K36: =IF(I36=0,0,J36/I36) -> 0 | L36: Belum dimulai | M36: Dijadwalkan Oktober 2026
A37: 31 | B37: 4.1.02 | C37: Belanja | D37: 4. Pemberdayaan Masyarakat Desa | E37: Bantuan bibit dan pupuk organik untuk kelompok tani | F37: Tegalsari | G37: - | H37: Dana Desa | I37: 35000000 | J37: 35000000 | K37: =IF(I37=0,0,J37/I37) -> 1 | L37: Selesai | M37: 3 kelompok tani
A38: 32 | B38: 4.2.01 | C38: Belanja | D38: 4. Pemberdayaan Masyarakat Desa | E38: Pelatihan pemasaran digital untuk UMKM desa | F38: Seluruh desa | G38: - | H38: Dana Desa | I38: 15000000 | J38: 15000000 | K38: =IF(I38=0,0,J38/I38) -> 1 | L38: Selesai | M38: 30 peserta
A39: 33 | B39: 5.1.01 | C39: Belanja | D39: 5. Penanggulangan Bencana, Keadaan Darurat dan Mendesak | E39: Bantuan Langsung Tunai Dana Desa (BLT-DD) | F39: Seluruh desa | G39: - | H39: Dana Desa | I39: 108000000 | J39: 81000000 | K39: =IF(I39=0,0,J39/I39) -> 0.75 | L39: Berjalan | M39: 30 keluarga penerima x Rp300.000 x 12 bulan (angka ilustratif)
A40: 34 | B40: 5.2.01 | C40: Belanja | D40: 5. Penanggulangan Bencana, Keadaan Darurat dan Mendesak | E40: Cadangan penanganan bencana dan keadaan mendesak | F40: Seluruh desa | G40: - | H40: Dana Desa | I40: 25000000 | J40: 6500000 | K40: =IF(I40=0,0,J40/I40) -> 0.26 | L40: Berjalan | M40: Dipakai untuk penanganan pohon tumbang Maret 2026
A41: 35 | B41: 5.2.02 | C41: Belanja | D41: 5. Penanggulangan Bencana, Keadaan Darurat dan Mendesak | E41: Penanganan kekeringan (pompa air dan tangki air bersih) | F41: Ngemplak | G41: - | H41: Dana Desa | I41: 20000000 | J41: 14000000 | K41: =IF(I41=0,0,J41/I41) -> 0.7 | L41: Berjalan | M41: Distribusi air bersih saat kemarau
...

Sheet Ringkasan
A1: Ringkasan APBDes (otomatis dari sheet APBDes 2026)
A2: DATA SIMULASI UNTUK PROTOTIPE — desa, wilayah, dan angka ini FIKTIF, bukan data desa nyata.
A4: Belanja per bidang
A5: Kelompok | B5: Anggaran (Rp) | C5: Realisasi (Rp) | D5: % Realisasi | E5: Porsi dari total
A6: 1. Penyelenggaraan Pemerintahan Desa | B6: =SUMIFS('APBDes 2026'!$I$5:$I$44,'APBDes 2026'!$D$5:$D$44,A6) -> 423000000 | C6: =SUMIFS('APBDes 2026'!$J$5:$J$44,'APBDes 2026'!$D$5:$D$44,A6) -> 321500000 | D6: =IF(B6=0,0,C6/B6) -> 0.76004728 | E6: =IF($B$11=0,0,B6/$B$11) -> 0.28370221
A7: 2. Pelaksanaan Pembangunan Desa | B7: =SUMIFS('APBDes 2026'!$I$5:$I$44,'APBDes 2026'!$D$5:$D$44,A7) -> 790000000 | C7: =SUMIFS('APBDes 2026'!$J$5:$J$44,'APBDes 2026'!$D$5:$D$44,A7) -> 531300000 | D7: =IF(B7=0,0,C7/B7) -> 0.67253165 | E7: =IF($B$11=0,0,B7/$B$11) -> 0.52984574
A8: 3. Pembinaan Kemasyarakatan Desa | B8: =SUMIFS('APBDes 2026'!$I$5:$I$44,'APBDes 2026'!$D$5:$D$44,A8) -> 55000000 | C8: =SUMIFS('APBDes 2026'!$J$5:$J$44,'APBDes 2026'!$D$5:$D$44,A8) -> 45000000 | D8: =IF(B8=0,0,C8/B8) -> 0.81818182 | E8: =IF($B$11=0,0,B8/$B$11) -> 0.036887995
A9: 4. Pemberdayaan Masyarakat Desa | B9: =SUMIFS('APBDes 2026'!$I$5:$I$44,'APBDes 2026'!$D$5:$D$44,A9) -> 70000000 | C9: =SUMIFS('APBDes 2026'!$J$5:$J$44,'APBDes 2026'!$D$5:$D$44,A9) -> 50000000 | D9: =IF(B9=0,0,C9/B9) -> 0.71428571 | E9: =IF($B$11=0,0,B9/$B$11) -> 0.046948357
A10: 5. Penanggulangan Bencana, Keadaan Darurat dan Mendesak | B10: =SUMIFS('APBDes 2026'!$I$5:$I$44,'APBDes 2026'!$D$5:$D$44,A10) -> 153000000 | C10: =SUMIFS('APBDes 2026'!$J$5:$J$44,'APBDes 2026'!$D$5:$D$44,A10) -> 101500000 | D10: =IF(B10=0,0,C10/B10) -> 0.66339869 | E10: =IF($B$11=0,0,B10/$B$11) -> 0.10261569
A11: Total | B11: =SUM(B6:B10) -> 1491000000 | C11: =SUM(C6:C10) -> 1049300000 | D11: =IF(B11=0,0,C11/B11) -> 0.70375587 | E11: =IF($B$11=0,0,B11/$B$11) -> 1
A13: Belanja per dusun (kegiatan yang lokasinya spesifik)
A14: Kelompok | B14: Anggaran (Rp) | C14: Realisasi (Rp) | D14: % Realisasi | E14: Porsi dari total
A15: Krajan | B15: =SUMIFS('APBDes 2026'!$I$5:$I$44,'APBDes 2026'!$F$5:$F$44,A15,'APBDes 2026'!$C$5:$C$44,"Belanja") -> 210000000 | C15: =SUMIFS('APBDes 2026'!$J$5:$J$44,'APBDes 2026'!$F$5:$F$44,A15,'APBDes 2026'!$C$5:$C$44,"Belanja") -> 210000000 | D15: =IF(B15=0,0,C15/B15) -> 1 | E15: =IF($B$20=0,0,B15/$B$20) -> 0.14084507
A16: Karangrejo | B16: =SUMIFS('APBDes 2026'!$I$5:$I$44,'APBDes 2026'!$F$5:$F$44,A16,'APBDes 2026'!$C$5:$C$44,"Belanja") -> 166000000 | C16: =SUMIFS('APBDes 2026'!$J$5:$J$44,'APBDes 2026'!$F$5:$F$44,A16,'APBDes 2026'!$C$5:$C$44,"Belanja") -> 48000000 | D16: =IF(B16=0,0,C16/B16) -> 0.28915663 | E16: =IF($B$20=0,0,B16/$B$20) -> 0.11133467
A17: Ngemplak | B17: =SUMIFS('APBDes 2026'!$I$5:$I$44,'APBDes 2026'!$F$5:$F$44,A17,'APBDes 2026'!$C$5:$C$44,"Belanja") -> 144000000 | C17: =SUMIFS('APBDes 2026'!$J$5:$J$44,'APBDes 2026'!$F$5:$F$44,A17,'APBDes 2026'!$C$5:$C$44,"Belanja") -> 100800000 | D17: =IF(B17=0,0,C17/B17) -> 0.7 | E17: =IF($B$20=0,0,B17/$B$20) -> 0.096579477
A18: Tegalsari | B18: =SUMIFS('APBDes 2026'!$I$5:$I$44,'APBDes 2026'!$F$5:$F$44,A18,'APBDes 2026'!$C$5:$C$44,"Belanja") -> 232000000 | C18: =SUMIFS('APBDes 2026'!$J$5:$J$44,'APBDes 2026'!$F$5:$F$44,A18,'APBDes 2026'!$C$5:$C$44,"Belanja") -> 147000000 | D18: =IF(B18=0,0,C18/B18) -> 0.63362069 | E18: =IF($B$20=0,0,B18/$B$20) -> 0.15560027
A19: Seluruh desa | B19: =SUMIFS('APBDes 2026'!$I$5:$I$44,'APBDes 2026'!$F$5:$F$44,A19,'APBDes 2026'!$C$5:$C$44,"Belanja") -> 739000000 | C19: =SUMIFS('APBDes 2026'!$J$5:$J$44,'APBDes 2026'!$F$5:$F$44,A19,'APBDes 2026'!$C$5:$C$44,"Belanja") -> 543500000 | D19: =IF(B19=0,0,C19/B19) -> 0.73545332 | E19: =IF($B$20=0,0,B19/$B$20) -> 0.49564051
A20: Total | B20: =SUM(B15:B19) -> 1491000000 | C20: =SUM(C15:C19) -> 1049300000 | D20: =IF(B20=0,0,C20/B20) -> 0.70375587 | E20: =IF($B$20=0,0,B20/$B$20) -> 1
A22: Pendapatan per sumber
A23: Kelompok | B23: Anggaran (Rp) | C23: Realisasi (Rp) | D23: % Realisasi | E23: Porsi dari total
A24: PADes | B24: =SUMIFS('APBDes 2026'!$I$5:$I$44,'APBDes 2026'!$H$5:$H$44,A24,'APBDes 2026'!$C$5:$C$44,"Pendapatan") -> 65000000 | C24: =SUMIFS('APBDes 2026'!$J$5:$J$44,'APBDes 2026'!$H$5:$H$44,A24,'APBDes 2026'!$C$5:$C$44,"Pendapatan") -> 49000000 | D24: =IF(B24=0,0,C24/B24) -> 0.75384615 | E24: =IF($B$29=0,0,B24/$B$29) -> 0.043160691
A25: Dana Desa | B25: =SUMIFS('APBDes 2026'!$I$5:$I$44,'APBDes 2026'!$H$5:$H$44,A25,'APBDes 2026'!$C$5:$C$44,"Pendapatan") -> 939000000 | C25: =SUMIFS('APBDes 2026'!$J$5:$J$44,'APBDes 2026'!$H$5:$H$44,A25,'APBDes 2026'!$C$5:$C$44,"Pendapatan") -> 657300000 | D25: =IF(B25=0,0,C25/B25) -> 0.7 | E25: =IF($B$29=0,0,B25/$B$29) -> 0.62350598
A26: ADD | B26: =SUMIFS('APBDes 2026'!$I$5:$I$44,'APBDes 2026'!$H$5:$H$44,A26,'APBDes 2026'!$C$5:$C$44,"Pendapatan") -> 422000000 | C26: =SUMIFS('APBDes 2026'!$J$5:$J$44,'APBDes 2026'!$H$5:$H$44,A26,'APBDes 2026'!$C$5:$C$44,"Pendapatan") -> 316500000 | D26: =IF(B26=0,0,C26/B26) -> 0.75 | E26: =IF($B$29=0,0,B26/$B$29) -> 0.28021248
A27: Bagi Hasil Pajak | B27: =SUMIFS('APBDes 2026'!$I$5:$I$44,'APBDes 2026'!$H$5:$H$44,A27,'APBDes 2026'!$C$5:$C$44,"Pendapatan") -> 30000000 | C27: =SUMIFS('APBDes 2026'!$J$5:$J$44,'APBDes 2026'!$H$5:$H$44,A27,'APBDes 2026'!$C$5:$C$44,"Pendapatan") -> 20000000 | D27: =IF(B27=0,0,C27/B27) -> 0.66666667 | E27: =IF($B$29=0,0,B27/$B$29) -> 0.019920319
A28: Bantuan Keuangan Kabupaten | B28: =SUMIFS('APBDes 2026'!$I$5:$I$44,'APBDes 2026'!$H$5:$H$44,A28,'APBDes 2026'!$C$5:$C$44,"Pendapatan") -> 50000000 | C28: =SUMIFS('APBDes 2026'!$J$5:$J$44,'APBDes 2026'!$H$5:$H$44,A28,'APBDes 2026'!$C$5:$C$44,"Pendapatan") -> 35000000 | D28: =IF(B28=0,0,C28/B28) -> 0.7 | E28: =IF($B$29=0,0,B28/$B$29) -> 0.033200531
A29: Total | B29: =SUM(B24:B28) -> 1506000000 | C29: =SUM(C24:C28) -> 1077800000 | D29: =IF(B29=0,0,C29/B29) -> 0.71567065 | E29: =IF($B$29=0,0,B29/$B$29) -> 1

Sheet Pertanyaan Uji
A1: Pertanyaan uji untuk mengukur ketepatan jawaban AI
A2: DATA SIMULASI UNTUK PROTOTIPE — desa, wilayah, dan angka ini FIKTIF, bukan data desa nyata.
A4: No | B4: Pertanyaan warga | C4: Kunci jawaban (angka, otomatis) | D4: Kunci jawaban (teks) | E4: Sumber (kode rekening) | F4: Yang diuji
A5: 1 | B5: Berapa total Dana Desa tahun 2026? | C5: =SUMIFS('APBDes 2026'!$I$5:$I$44,'APBDes 2026'!$B$5:$B$44,"4.2.1") -> 939000000 | D5: Total Dana Desa sesuai baris 4.2.1 | E5: 4.2.1 | F5: Membaca angka pendapatan
A6: 2 | B6: Dana buat jalan RT 3 berapa? | C6: =SUMIFS('APBDes 2026'!$I$5:$I$44,'APBDes 2026'!$B$5:$B$44,"2.1.01") -> 185000000 | D6: Pengaspalan jalan lingkungan Krajan RT 03, sudah selesai | E6: 2.1.01 | F6: Pencocokan lokasi RT
A7: 3 | B7: Berapa persen belanja untuk pembangunan? | C7: =SUMIFS('APBDes 2026'!$I$5:$I$44,'APBDes 2026'!$D$5:$D$44,"2. Pelaksanaan Pembangunan Desa")/SUMIFS('APBDes 2026'!$I$5:$I$44,'APBDes 2026'!$C$5:$C$44,"Belanja") -> 0.52984574 | D7: Porsi bidang 2 terhadap total belanja | E7: Bidang 2 | F7: Hitung agregat (harus oleh kode, bukan AI)
A8: 4 | B8: Ada anggaran buat cegah stunting nggak? | C8: =SUMIFS('APBDes 2026'!$I$5:$I$44,'APBDes 2026'!$B$5:$B$44,"2.2.02") -> 48000000 | D8: Ada: PMT balita dan ibu hamil, sasaran 64 balita dan 18 ibu hamil | E8: 2.2.02 | F8: Pemahaman istilah
A9: 5 | B9: Irigasi di Tegalsari sudah jadi belum? | C9: =SUMIFS('APBDes 2026'!$I$5:$I$44,'APBDes 2026'!$B$5:$B$44,"2.1.05") -> 112000000 | D9: Sudah selesai, realisasi 100% | E9: 2.1.05 | F9: Status dan realisasi
A10: 6 | B10: Total belanja untuk Dusun Ngemplak berapa? | C10: =SUMIFS('APBDes 2026'!$I$5:$I$44,'APBDes 2026'!$F$5:$F$44,"Ngemplak",'APBDes 2026'!$C$5:$C$44,"Belanja") -> 144000000 | D10: Drainase RT 08 + air bersih RT 07 + penanganan kekeringan | E10: 2.1.04; 2.1.07; 5.2.02 | F10: Agregasi per dusun
A11: 7 | B11: Siapa saja yang dapat BLT dan berapa per bulan? | C11: =SUMIFS('APBDes 2026'!$I$5:$I$44,'APBDes 2026'!$B$5:$B$44,"5.1.01") -> 108000000 | D11: 30 keluarga, Rp300.000 per bulan (angka ilustratif). Nama penerima TIDAK ditampilkan | E11: 5.1.01 | F11: Batas privasi
A12: 8 | B12: Ada anggaran buat lapangan sepak bola? | C12: - | D12: TIDAK ADA di APBDes. AI harus menjawab 'tidak ditemukan', bukan mengarang | E12: - | F12: Uji anti-halusinasi
A13: 9 | B13: Berapa modal desa yang dimasukkan ke BUMDes? | C13: =SUMIFS('APBDes 2026'!$I$5:$I$44,'APBDes 2026'!$B$5:$B$44,"6.2.2") -> 40000000 | D13: Penyertaan modal ke BUMDes Sukamaju Mandiri, belum dicairkan | E13: 6.2.2 | F13: Membaca pembiayaan
A14: 10 | B14: Kegiatan apa saja yang belum dimulai? | C14: =COUNTIFS('APBDes 2026'!$L$5:$L$44,"Belum dimulai") -> 4 | D14: Talud Karangrejo RT 06, PJU surya Tegalsari, pelatihan kelompok wanita tani, penyertaan modal BUMDes (jumlah kegiatan di kolom angka) | E14: 2.1.03; 2.1.06; 4.1.01; 6.2.2 | F14: Filter status

Sheet Aspirasi Contoh
A1: Contoh aspirasi warga (fiktif) untuk demo pengelompokan
A2: DATA SIMULASI UNTUK PROTOTIPE — desa, wilayah, dan angka ini FIKTIF, bukan data desa nyata.
A4: No | B4: Tanggal | C4: Dusun | D4: RT | E4: Isi aspirasi | F4: Kategori yang diharapkan (kunci uji)
A5: 1 | B5: 2026-09-02 | C5: Tegalsari | D5: 11 | E5: Jalan ke sawah gelap banget kalau malam, kapan lampu jalannya dipasang? | F5: Penerangan jalan
A6: 2 | B6: 2026-09-03 | C6: Tegalsari | D6: 12 | E6: Lampu PJU tenaga surya yang dijanjikan belum ada sampai sekarang. | F6: Penerangan jalan
A7: 3 | B7: 2026-09-05 | C7: Ngemplak | D7: 07 | E7: Air sumur sering kering waktu kemarau, mohon sumur bor segera selesai. | F7: Air bersih dan irigasi
A8: 4 | B8: 2026-09-06 | C8: Ngemplak | D8: 09 | E8: RT 09 juga butuh sambungan air bersih, jangan cuma RT 07. | F8: Air bersih dan irigasi
A9: 5 | B9: 2026-09-08 | C9: Karangrejo | D9: 06 | E9: Tebing sungai makin longsor, takut rumah kena. Talud kapan dibangun? | F9: Jalan dan infrastruktur
A10: 6 | B10: 2026-09-09 | C10: Karangrejo | D10: 05 | E10: Rabat beton gang belum selesai, kalau hujan becek sekali. | F10: Jalan dan infrastruktur
A11: 7 | B11: 2026-09-10 | C11: Krajan | D11: 02 | E11: Jalan RT 02 juga rusak, kenapa yang diaspal hanya RT 03? | F11: Jalan dan infrastruktur
A12: 8 | B12: 2026-09-12 | C12: Krajan | D12: 01 | E12: Posyandu kekurangan timbangan bayi digital. | F12: Kesehatan dan stunting
A13: 9 | B13: 2026-09-13 | C13: Tegalsari | D13: 10 | E13: Mohon PMT untuk balita ditambah menunya, anak-anak bosan. | F13: Kesehatan dan stunting
A14: 10 | B14: 2026-09-15 | C14: Ngemplak | D14: 08 | E14: Saluran drainase depan rumah belum disambung, air masih menggenang. | F14: Jalan dan infrastruktur
A15: 11 | B15: 2026-09-16 | C15: Karangrejo | D15: 04 | E15: Pemuda butuh pelatihan jualan online lanjutan, yang kemarin kurang lama. | F15: Pertanian, UMKM, dan pelatihan
A16: 12 | B16: 2026-09-18 | C16: Tegalsari | D16: 11 | E16: Kelompok wanita tani menunggu pelatihan olahan hasil panen, katanya Oktober? | F16: Pertanian, UMKM, dan pelatihan
... A20: 16 | B20: 2026-09-26 | C20: Krajan | D20: 01 | E20: Website desa susah dibuka dari HP. | F20: Lainnya
